[2023-05-31T23:07:40.317+0000] {taskinstance.py:1103} INFO - Dependencies all met for dep_context=non-requeueable deps ti=<TaskInstance: docs_example_dag.tell_me_what_to_do scheduled__2023-05-30T00:00:00+00:00 [queued]>
[2023-05-31T23:07:40.321+0000] {taskinstance.py:1103} INFO - Dependencies all met for dep_context=requeueable deps ti=<TaskInstance: docs_example_dag.tell_me_what_to_do scheduled__2023-05-30T00:00:00+00:00 [queued]>
[2023-05-31T23:07:40.322+0000] {taskinstance.py:1308} INFO - Starting attempt 2 of 2
[2023-05-31T23:07:40.328+0000] {taskinstance.py:1327} INFO - Executing <Task(_PythonDecoratedOperator): tell_me_what_to_do> on 2023-05-30 00:00:00+00:00
[2023-05-31T23:07:40.331+0000] {standard_task_runner.py:57} INFO - Started process 141 to run task
[2023-05-31T23:07:40.333+0000] {standard_task_runner.py:84} INFO - Running: ['***', 'tasks', 'run', 'docs_example_dag', 'tell_me_what_to_do', 'scheduled__2023-05-30T00:00:00+00:00', '--job-id', '11', '--raw', '--subdir', 'DAGS_FOLDER/Csv2Delta/dags/Csv2Delta_dag.py', '--cfg-path', '/tmp/tmpkzdgmzso']
[2023-05-31T23:07:40.333+0000] {standard_task_runner.py:85} INFO - Job 11: Subtask tell_me_what_to_do
[2023-05-31T23:07:40.360+0000] {task_command.py:410} INFO - Running <TaskInstance: docs_example_dag.tell_me_what_to_do scheduled__2023-05-30T00:00:00+00:00 [running]> on host 58054f4efef6
[2023-05-31T23:07:40.396+0000] {taskinstance.py:1545} INFO - Exporting env vars: AIRFLOW_CTX_DAG_EMAIL='phomsophaN@saccounty.net' AIRFLOW_CTX_DAG_OWNER='***' AIRFLOW_CTX_DAG_ID='docs_example_dag' AIRFLOW_CTX_TASK_ID='tell_me_what_to_do' AIRFLOW_CTX_EXECUTION_DATE='2023-05-30T00:00:00+00:00' AIRFLOW_CTX_TRY_NUMBER='2' AIRFLOW_CTX_DAG_RUN_ID='scheduled__2023-05-30T00:00:00+00:00'
[2023-05-31T23:07:40.396+0000] {taskinstance.py:1824} ERROR - Task failed with exception
Traceback (most recent call last):
  File "/home/airflow/.local/lib/python3.10/site-packages/airflow/decorators/base.py", line 220, in execute
    return_value = super().execute(context)
  File "/home/airflow/.local/lib/python3.10/site-packages/airflow/operators/python.py", line 181, in execute
    return_value = self.execute_callable()
  File "/home/airflow/.local/lib/python3.10/site-packages/airflow/operators/python.py", line 198, in execute_callable
    return self.python_callable(*self.op_args, **self.op_kwargs)
  File "/opt/airflow/dags/Csv2Delta/dags/Csv2Delta_dag.py", line 32, in tell_me_what_to_do
    response = requests.get("https://www.boredapi.com/api/activity")
NameError: name 'requests' is not defined
[2023-05-31T23:07:40.402+0000] {taskinstance.py:1345} INFO - Marking task as FAILED. dag_id=docs_example_dag, task_id=tell_me_what_to_do, execution_date=20230530T000000, start_date=20230531T230740, end_date=20230531T230740
[2023-05-31T23:07:40.408+0000] {standard_task_runner.py:104} ERROR - Failed to execute job 11 for task tell_me_what_to_do (name 'requests' is not defined; 141)
[2023-05-31T23:07:40.424+0000] {local_task_job_runner.py:225} INFO - Task exited with return code 1
[2023-05-31T23:07:40.434+0000] {taskinstance.py:2651} INFO - 0 downstream tasks scheduled from follow-on schedule check
