[2023-06-08T18:25:53.742+0000] {taskinstance.py:1103} INFO - Dependencies all met for dep_context=non-requeueable deps ti=<TaskInstance: wrapper_ex_dag.execute_function_task manual__2023-06-08T18:20:49.809090+00:00 [queued]>
[2023-06-08T18:25:53.746+0000] {taskinstance.py:1103} INFO - Dependencies all met for dep_context=requeueable deps ti=<TaskInstance: wrapper_ex_dag.execute_function_task manual__2023-06-08T18:20:49.809090+00:00 [queued]>
[2023-06-08T18:25:53.746+0000] {taskinstance.py:1308} INFO - Starting attempt 2 of 2
[2023-06-08T18:25:53.752+0000] {taskinstance.py:1327} INFO - Executing <Task(_PythonDecoratedOperator): execute_function_task> on 2023-06-08 18:20:49.809090+00:00
[2023-06-08T18:25:53.755+0000] {standard_task_runner.py:57} INFO - Started process 288 to run task
[2023-06-08T18:25:53.758+0000] {standard_task_runner.py:84} INFO - Running: ['***', 'tasks', 'run', 'wrapper_ex_dag', 'execute_function_task', 'manual__2023-06-08T18:20:49.809090+00:00', '--job-id', '233', '--raw', '--subdir', 'DAGS_FOLDER/Python-Delta-Lake/custom_dags/WrapperDag.py', '--cfg-path', '/tmp/tmp1w3x5nag']
[2023-06-08T18:25:53.759+0000] {standard_task_runner.py:85} INFO - Job 233: Subtask execute_function_task
[2023-06-08T18:25:53.783+0000] {task_command.py:410} INFO - Running <TaskInstance: wrapper_ex_dag.execute_function_task manual__2023-06-08T18:20:49.809090+00:00 [running]> on host c712b1d8680f
[2023-06-08T18:25:53.826+0000] {taskinstance.py:1545} INFO - Exporting env vars: AIRFLOW_CTX_DAG_EMAIL='phomsophaN@saccounty.net' AIRFLOW_CTX_DAG_OWNER='***' AIRFLOW_CTX_DAG_ID='wrapper_ex_dag' AIRFLOW_CTX_TASK_ID='execute_function_task' AIRFLOW_CTX_EXECUTION_DATE='2023-06-08T18:20:49.809090+00:00' AIRFLOW_CTX_TRY_NUMBER='2' AIRFLOW_CTX_DAG_RUN_ID='manual__2023-06-08T18:20:49.809090+00:00'
[2023-06-08T18:25:53.826+0000] {logging_mixin.py:149} INFO - CSV Delta Class Initialted
[2023-06-08T18:25:53.827+0000] {CsvDagWrapper.py:23} INFO - CSV Delta Class Initialted
[2023-06-08T18:25:53.827+0000] {logging_mixin.py:149} INFO - Environment successfully parsed! Environment is Local
[2023-06-08T18:25:53.827+0000] {CsvDagWrapper.py:29} INFO - Environment successfully parsed! Environment is Local
[2023-06-08T18:25:53.827+0000] {logging_mixin.py:149} INFO - Table/s successfully parsed! Table:  CASE
[2023-06-08T18:25:53.827+0000] {CsvDagWrapper.py:34} INFO - Table/s successfully parsed! Table:  CASE
[2023-06-08T18:25:53.827+0000] {CsvDagWrapper.py:36} INFO - Works so far....
[2023-06-08T18:25:55.743+0000] {logging_mixin.py:149} INFO - Stopping Spark App
[2023-06-08T18:25:55.744+0000] {CsvDagWrapper.py:39} INFO - test
[2023-06-08T18:25:58.209+0000] {taskinstance.py:1824} ERROR - Task failed with exception
Traceback (most recent call last):
  File "/home/airflow/.local/lib/python3.10/site-packages/airflow/decorators/base.py", line 220, in execute
    return_value = super().execute(context)
  File "/home/airflow/.local/lib/python3.10/site-packages/airflow/operators/python.py", line 181, in execute
    return_value = self.execute_callable()
  File "/home/airflow/.local/lib/python3.10/site-packages/airflow/operators/python.py", line 198, in execute_callable
    return self.python_callable(*self.op_args, **self.op_kwargs)
  File "/opt/airflow/dags/Python-Delta-Lake/custom_dags/WrapperDag.py", line 46, in execute_function_task
    task.RunCsvToDelta("Local","CASE",False)
  File "/opt/airflow/dags/Python-Delta-Lake/Csv2Delta/CsvDagWrapper.py", line 41, in RunCsvToDelta
    spark.sql(f"use {database_name}")
  File "/home/airflow/.local/lib/python3.10/site-packages/pyspark/sql/session.py", line 1034, in sql
    return DataFrame(self._jsparkSession.sql(sqlQuery), self)
  File "/home/airflow/.local/lib/python3.10/site-packages/py4j/java_gateway.py", line 1321, in __call__
    return_value = get_return_value(
  File "/home/airflow/.local/lib/python3.10/site-packages/pyspark/sql/utils.py", line 196, in deco
    raise converted from None
pyspark.sql.utils.AnalysisException: Database 'calsaws' not found
[2023-06-08T18:25:58.217+0000] {taskinstance.py:1345} INFO - Marking task as FAILED. dag_id=wrapper_ex_dag, task_id=execute_function_task, execution_date=20230608T182049, start_date=20230608T182553, end_date=20230608T182558
[2023-06-08T18:25:58.225+0000] {standard_task_runner.py:104} ERROR - Failed to execute job 233 for task execute_function_task (Database 'calsaws' not found; 288)
[2023-06-08T18:25:58.267+0000] {local_task_job_runner.py:225} INFO - Task exited with return code 1
[2023-06-08T18:25:58.276+0000] {taskinstance.py:2651} INFO - 0 downstream tasks scheduled from follow-on schedule check
