[2023-06-01T17:25:25.582+0000] {taskinstance.py:1103} INFO - Dependencies all met for dep_context=non-requeueable deps ti=<TaskInstance: test_external_op_py_logging.external_op manual__2023-06-01T17:25:23.973556+00:00 [queued]>
[2023-06-01T17:25:25.587+0000] {taskinstance.py:1103} INFO - Dependencies all met for dep_context=requeueable deps ti=<TaskInstance: test_external_op_py_logging.external_op manual__2023-06-01T17:25:23.973556+00:00 [queued]>
[2023-06-01T17:25:25.587+0000] {taskinstance.py:1308} INFO - Starting attempt 1 of 1
[2023-06-01T17:25:25.594+0000] {taskinstance.py:1327} INFO - Executing <Task(_PythonExternalDecoratedOperator): external_op> on 2023-06-01 17:25:23.973556+00:00
[2023-06-01T17:25:25.597+0000] {standard_task_runner.py:57} INFO - Started process 53 to run task
[2023-06-01T17:25:25.599+0000] {standard_task_runner.py:84} INFO - Running: ['***', 'tasks', 'run', 'test_external_op_py_logging', 'external_op', 'manual__2023-06-01T17:25:23.973556+00:00', '--job-id', '83', '--raw', '--subdir', 'DAGS_FOLDER/Csv2Delta/dags/Csv2Delta_dag.py', '--cfg-path', '/tmp/tmp1dmrvvgp']
[2023-06-01T17:25:25.599+0000] {standard_task_runner.py:85} INFO - Job 83: Subtask external_op
[2023-06-01T17:25:25.626+0000] {task_command.py:410} INFO - Running <TaskInstance: test_external_op_py_logging.external_op manual__2023-06-01T17:25:23.973556+00:00 [running]> on host 699164ff75ed
[2023-06-01T17:25:25.662+0000] {taskinstance.py:1545} INFO - Exporting env vars: AIRFLOW_CTX_DAG_OWNER='***' AIRFLOW_CTX_DAG_ID='test_external_op_py_logging' AIRFLOW_CTX_TASK_ID='external_op' AIRFLOW_CTX_EXECUTION_DATE='2023-06-01T17:25:23.973556+00:00' AIRFLOW_CTX_TRY_NUMBER='1' AIRFLOW_CTX_DAG_RUN_ID='manual__2023-06-01T17:25:23.973556+00:00'
[2023-06-01T17:25:25.663+0000] {python.py:740} WARNING - When checking for Airflow installed in venv got [Errno 2] No such file or directory: '/bin/python'
[2023-06-01T17:25:25.664+0000] {python.py:741} WARNING - This means that Airflow is not properly installed by  /bin/python. Airflow context keys will not be available. Please Install Airflow 2.6.1 in your environment to access them.
[2023-06-01T17:25:25.665+0000] {taskinstance.py:1824} ERROR - Task failed with exception
Traceback (most recent call last):
  File "/home/airflow/.local/lib/python3.10/site-packages/airflow/decorators/base.py", line 220, in execute
    return_value = super().execute(context)
  File "/home/airflow/.local/lib/python3.10/site-packages/airflow/operators/python.py", line 369, in execute
    return super().execute(context=serializable_context)
  File "/home/airflow/.local/lib/python3.10/site-packages/airflow/operators/python.py", line 181, in execute
    return_value = self.execute_callable()
  File "/home/airflow/.local/lib/python3.10/site-packages/airflow/operators/python.py", line 673, in execute_callable
    raise ValueError(f"Python Path '{python_path}' must exists")
ValueError: Python Path '/bin/python' must exists
[2023-06-01T17:25:25.669+0000] {taskinstance.py:1345} INFO - Marking task as FAILED. dag_id=test_external_op_py_logging, task_id=external_op, execution_date=20230601T172523, start_date=20230601T172525, end_date=20230601T172525
[2023-06-01T17:25:25.675+0000] {standard_task_runner.py:104} ERROR - Failed to execute job 83 for task external_op (Python Path '/bin/python' must exists; 53)
[2023-06-01T17:25:25.690+0000] {local_task_job_runner.py:225} INFO - Task exited with return code 1
[2023-06-01T17:25:25.702+0000] {taskinstance.py:2651} INFO - 0 downstream tasks scheduled from follow-on schedule check
